sample_input.txt
  12345   BUY    BTCUSD      5   10000  
 zod42   SELL BTCUSD    2   10001   
 13471    BUY BTCUSD    6       9971
    11431 BUY ETHUSD 9 175
    abe14 SELL BTCUSD 7 9800
    plu401 SELL ETHUSD 5 170
    45691 BUY ETHUSD 3 180
